2025-05-10 20:59:49,049 INFO    MainThread:860683 [wandb_setup.py:_flush():67] Current SDK version is 0.19.7
2025-05-10 20:59:49,050 INFO    MainThread:860683 [wandb_setup.py:_flush():67] Configure stats pid to 860683
2025-05-10 20:59:49,050 INFO    MainThread:860683 [wandb_setup.py:_flush():67] Loading settings from /ceph/hpc/home/dv70648/.config/wandb/settings
2025-05-10 20:59:49,050 INFO    MainThread:860683 [wandb_setup.py:_flush():67] Loading settings from /ceph/hpc/data/s24o01-42-users/translation_optimization/trl/wandb/settings
2025-05-10 20:59:49,050 INFO    MainThread:860683 [wandb_setup.py:_flush():67] Loading settings from environment variables
2025-05-10 20:59:49,050 INFO    MainThread:860683 [wandb_init.py:setup_run_log_directory():647] Logging user logs to /ceph/hpc/data/s24o01-42-users/translation_optimization/trl/wandb/run-20250510_205949-8y8rrm6q/logs/debug.log
2025-05-10 20:59:49,050 INFO    MainThread:860683 [wandb_init.py:setup_run_log_directory():648] Logging internal logs to /ceph/hpc/data/s24o01-42-users/translation_optimization/trl/wandb/run-20250510_205949-8y8rrm6q/logs/debug-internal.log
2025-05-10 20:59:49,050 INFO    MainThread:860683 [wandb_init.py:init():761] calling init triggers
2025-05-10 20:59:49,050 INFO    MainThread:860683 [wandb_init.py:init():766] wandb.init called with sweep_config: {}
config: {'_wandb': {}}
2025-05-10 20:59:49,050 INFO    MainThread:860683 [wandb_init.py:init():784] starting backend
2025-05-10 20:59:49,050 INFO    MainThread:860683 [wandb_init.py:init():788] sending inform_init request
2025-05-10 20:59:49,055 INFO    MainThread:860683 [backend.py:_multiprocessing_setup():97] multiprocessing start_methods=fork,spawn,forkserver, using: spawn
2025-05-10 20:59:49,059 INFO    MainThread:860683 [wandb_init.py:init():803] backend started and connected
2025-05-10 20:59:49,061 INFO    MainThread:860683 [wandb_init.py:init():896] updated telemetry
2025-05-10 20:59:49,062 INFO    MainThread:860683 [wandb_init.py:init():920] communicating run to backend with 90.0 second timeout
2025-05-10 20:59:49,306 ERROR   MainThread:860683 [wandb_init.py:init():1481] error in wandb.init()
Traceback (most recent call last):
  File "/usr/local/lib/python3.10/dist-packages/wandb/sdk/wandb_init.py", line 1471, in init
    return wi.init(run_settings, run_config)
  File "/usr/local/lib/python3.10/dist-packages/wandb/sdk/wandb_init.py", line 968, in init
    raise error
wandb.errors.errors.CommError: failed to upsert bucket: api: failed sending: POST https://api.wandb.ai/graphql giving up after 1 attempt(s): Post "https://api.wandb.ai/graphql": tls: failed to verify certificate: x509: certificate signed by unknown authority
2025-05-10 20:59:49,563 WARNING MsgRouterThr:860683 [router.py:message_loop():77] message_loop has been closed
Traceback (most recent call last):
  File "/usr/local/lib/python3.10/dist-packages/wandb/sdk/interface/router_sock.py", line 28, in _read_message
    resp = self._sock_client.read_server_response(timeout=1)
  File "/usr/local/lib/python3.10/dist-packages/wandb/sdk/lib/sock_client.py", line 285, in read_server_response
    data = self._read_packet_bytes(timeout=timeout)
  File "/usr/local/lib/python3.10/dist-packages/wandb/sdk/lib/sock_client.py", line 270, in _read_packet_bytes
    raise SockClientClosedError
wandb.sdk.lib.sock_client.SockClientClosedError

The above exception was the direct cause of the following exception:

Traceback (most recent call last):
  File "/usr/local/lib/python3.10/dist-packages/wandb/sdk/interface/router.py", line 70, in message_loop
    msg = self._read_message()
  File "/usr/local/lib/python3.10/dist-packages/wandb/sdk/interface/router_sock.py", line 30, in _read_message
    raise MessageRouterClosedError from e
wandb.sdk.interface.router.MessageRouterClosedError
2025-05-10 20:59:49,565 INFO    MsgRouterThr:860683 [mailbox.py:close():115] Closing mailbox, abandoning 0 handles.
