2025-06-12 21:11:18,727 INFO    MainThread:3245609 [wandb_setup.py:_flush():67] Current SDK version is 0.19.7
2025-06-12 21:11:18,727 INFO    MainThread:3245609 [wandb_setup.py:_flush():67] Configure stats pid to 3245609
2025-06-12 21:11:18,727 INFO    MainThread:3245609 [wandb_setup.py:_flush():67] Loading settings from /ceph/hpc/home/dv70648/.config/wandb/settings
2025-06-12 21:11:18,727 INFO    MainThread:3245609 [wandb_setup.py:_flush():67] Loading settings from /ceph/hpc/data/s24o01-42-users/translation_optimization/trl/wandb/settings
2025-06-12 21:11:18,727 INFO    MainThread:3245609 [wandb_setup.py:_flush():67] Loading settings from environment variables
2025-06-12 21:11:18,727 INFO    MainThread:3245609 [wandb_init.py:setup_run_log_directory():647] Logging user logs to /ceph/hpc/data/s24o01-42-users/translation_optimization/trl/wandb/run-20250612_211118-koeafl1m/logs/debug.log
2025-06-12 21:11:18,727 INFO    MainThread:3245609 [wandb_init.py:setup_run_log_directory():648] Logging internal logs to /ceph/hpc/data/s24o01-42-users/translation_optimization/trl/wandb/run-20250612_211118-koeafl1m/logs/debug-internal.log
2025-06-12 21:11:18,727 INFO    MainThread:3245609 [wandb_init.py:init():761] calling init triggers
2025-06-12 21:11:18,727 INFO    MainThread:3245609 [wandb_init.py:init():766] wandb.init called with sweep_config: {}
config: {'_wandb': {}}
2025-06-12 21:11:18,727 INFO    MainThread:3245609 [wandb_init.py:init():784] starting backend
2025-06-12 21:11:18,727 INFO    MainThread:3245609 [wandb_init.py:init():788] sending inform_init request
2025-06-12 21:11:18,734 INFO    MainThread:3245609 [backend.py:_multiprocessing_setup():97] multiprocessing start_methods=fork,spawn,forkserver, using: spawn
2025-06-12 21:11:18,735 INFO    MainThread:3245609 [wandb_init.py:init():803] backend started and connected
2025-06-12 21:11:18,736 INFO    MainThread:3245609 [wandb_init.py:init():896] updated telemetry
2025-06-12 21:11:18,741 INFO    MainThread:3245609 [wandb_init.py:init():920] communicating run to backend with 90.0 second timeout
2025-06-12 21:12:48,744 ERROR   MainThread:3245609 [wandb_init.py:init():1481] error in wandb.init()
Traceback (most recent call last):
  File "/usr/lib/python3.10/asyncio/locks.py", line 214, in wait
    await fut
asyncio.exceptions.CancelledError

During handling of the above exception, another exception occurred:

Traceback (most recent call last):
  File "/usr/lib/python3.10/asyncio/tasks.py", line 456, in wait_for
    return fut.result()
asyncio.exceptions.CancelledError

The above exception was the direct cause of the following exception:

Traceback (most recent call last):
  File "/usr/local/lib/python3.10/dist-packages/wandb/sdk/mailbox/handles.py", line 141, in wait_async
    await asyncio.wait_for(evt.wait(), timeout=timeout)
  File "/usr/lib/python3.10/asyncio/tasks.py", line 458, in wait_for
    raise exceptions.TimeoutError() from exc
asyncio.exceptions.TimeoutError

The above exception was the direct cause of the following exception:

Traceback (most recent call last):
  File "/usr/local/lib/python3.10/dist-packages/wandb/sdk/wandb_init.py", line 946, in init
    result = wait_with_progress(
  File "/usr/local/lib/python3.10/dist-packages/wandb/sdk/mailbox/wait_with_progress.py", line 23, in wait_with_progress
    return wait_all_with_progress(
  File "/usr/local/lib/python3.10/dist-packages/wandb/sdk/mailbox/wait_with_progress.py", line 86, in wait_all_with_progress
    return asyncio_compat.run(progress_loop_with_timeout)
  File "/usr/local/lib/python3.10/dist-packages/wandb/sdk/lib/asyncio_compat.py", line 30, in run
    return future.result()
  File "/usr/lib/python3.10/concurrent/futures/_base.py", line 458, in result
    return self.__get_result()
  File "/usr/lib/python3.10/concurrent/futures/_base.py", line 403, in __get_result
    raise self._exception
  File "/usr/lib/python3.10/concurrent/futures/thread.py", line 58, in run
    result = self.fn(*self.args, **self.kwargs)
  File "/usr/local/lib/python3.10/dist-packages/wandb/sdk/lib/asyncio_compat.py", line 74, in run
    return asyncio.run(self._run_or_cancel(fn))
  File "/usr/lib/python3.10/asyncio/runners.py", line 44, in run
    return loop.run_until_complete(main)
  File "/usr/lib/python3.10/asyncio/base_events.py", line 649, in run_until_complete
    return future.result()
  File "/usr/local/lib/python3.10/dist-packages/wandb/sdk/lib/asyncio_compat.py", line 98, in _run_or_cancel
    return fn_task.result()
  File "/usr/local/lib/python3.10/dist-packages/wandb/sdk/mailbox/wait_with_progress.py", line 81, in progress_loop_with_timeout
    return await _wait_handles_async(
  File "/usr/local/lib/python3.10/dist-packages/wandb/sdk/mailbox/wait_with_progress.py", line 129, in _wait_handles_async
    async with asyncio_compat.open_task_group() as task_group:
  File "/usr/lib/python3.10/contextlib.py", line 206, in __aexit__
    await anext(self.gen)
  File "/usr/local/lib/python3.10/dist-packages/wandb/sdk/lib/asyncio_compat.py", line 190, in open_task_group
    await task_group._wait_all()
  File "/usr/local/lib/python3.10/dist-packages/wandb/sdk/lib/asyncio_compat.py", line 159, in _wait_all
    raise exc
  File "/usr/local/lib/python3.10/dist-packages/wandb/sdk/mailbox/wait_with_progress.py", line 127, in wait_single
    results[index] = await handle.wait_async(timeout=timeout)
  File "/usr/local/lib/python3.10/dist-packages/wandb/sdk/mailbox/handles.py", line 150, in wait_async
    raise TimeoutError(
TimeoutError: Timed out waiting for response on palf9wfwmq7b

During handling of the above exception, another exception occurred:

Traceback (most recent call last):
  File "/usr/local/lib/python3.10/dist-packages/wandb/sdk/wandb_init.py", line 1471, in init
    return wi.init(run_settings, run_config)
  File "/usr/local/lib/python3.10/dist-packages/wandb/sdk/wandb_init.py", line 959, in init
    raise CommError(
wandb.errors.errors.CommError: Run initialization has timed out after 90.0 sec. Please try increasing the timeout with the `init_timeout` setting: `wandb.init(settings=wandb.Settings(init_timeout=120))`.
2025-06-12 21:12:49,005 WARNING MsgRouterThr:3245609 [router.py:message_loop():77] message_loop has been closed
Traceback (most recent call last):
  File "/usr/local/lib/python3.10/dist-packages/wandb/sdk/interface/router_sock.py", line 28, in _read_message
    resp = self._sock_client.read_server_response(timeout=1)
  File "/usr/local/lib/python3.10/dist-packages/wandb/sdk/lib/sock_client.py", line 285, in read_server_response
    data = self._read_packet_bytes(timeout=timeout)
  File "/usr/local/lib/python3.10/dist-packages/wandb/sdk/lib/sock_client.py", line 270, in _read_packet_bytes
    raise SockClientClosedError
wandb.sdk.lib.sock_client.SockClientClosedError

The above exception was the direct cause of the following exception:

Traceback (most recent call last):
  File "/usr/local/lib/python3.10/dist-packages/wandb/sdk/interface/router.py", line 70, in message_loop
    msg = self._read_message()
  File "/usr/local/lib/python3.10/dist-packages/wandb/sdk/interface/router_sock.py", line 30, in _read_message
    raise MessageRouterClosedError from e
wandb.sdk.interface.router.MessageRouterClosedError
2025-06-12 21:12:49,008 INFO    MsgRouterThr:3245609 [mailbox.py:close():115] Closing mailbox, abandoning 1 handles.
