cpu-bind=MASK - gn01, task  0  0 [3233292]: mask 0xffff0000ffff0000ffffffffffffffffffff0000ffff0000ffffffffffffffff set
*******STARTING********
--- Running on Node Rank: 0 ---
Total Nodes: 3
--- CUDA_VISIBLE_DEVICES for this srun task: 0,1,2,3 ---
GPUs per Node: 4
Master Address: gn01
Master Port: 29500
-------------------------------------------
accelerate launch     --config_file /ceph/hpc/data/s24o01-42-users/translation_optimization/trl/accelerate_config.yaml     --num_machines 3     --machine_rank 0     --main_process_ip gn01     --main_process_port 29500     --num_processes 12     --deepspeed_hostfile /ceph/hpc/data/s24o01-42-users/translation_optimization/trl/result_dir/hostfile_63107303     --deepspeed_multinode_launcher standard     --rdzv_backend static     --same_network     --mixed_precision bf16     "train_curriculum.py"     --rank=64 --learning_rate=4e-7 --total_epochs=3 --beta=0.1 --curriculum_stage=1
-------------------------------------------
[2025-06-12 18:09:01,035] [INFO] [real_accelerator.py:222:get_accelerator] Setting ds_accelerator to cuda (auto detect)
W0612 18:09:02.475000 3233343 torch/distributed/run.py:792] 
W0612 18:09:02.475000 3233343 torch/distributed/run.py:792] *****************************************
W0612 18:09:02.475000 3233343 torch/distributed/run.py:792] Setting OMP_NUM_THREADS environment variable for each process to be 1 in default, to avoid your system being overloaded, please further tune the variable for optimal performance in your application as needed. 
W0612 18:09:02.475000 3233343 torch/distributed/run.py:792] *****************************************
[2025-06-12 18:09:56,817] [INFO] [real_accelerator.py:222:get_accelerator] Setting ds_accelerator to cuda (auto detect)
[2025-06-12 18:09:56,839] [INFO] [real_accelerator.py:222:get_accelerator] Setting ds_accelerator to cuda (auto detect)
[2025-06-12 18:09:56,851] [INFO] [real_accelerator.py:222:get_accelerator] Setting ds_accelerator to cuda (auto detect)
[2025-06-12 18:09:56,859] [INFO] [real_accelerator.py:222:get_accelerator] Setting ds_accelerator to cuda (auto detect)
[load_data_curriculum.py]: Training data of type 'bad_lang_examples':    3489
[load_data_curriculum.py]: Training data of type 'short_examples':       699
[load_data_curriculum.py]: Training data of type 'choose_examples':      13379
[load_data_curriculum.py]: Training data of type 'bad_format_examples':  3148
[load_data_curriculum.py]: *[load_data_curriculum.py]: *[load_data_curriculum.py]: *[load_data_curriculum.py]: *[load_data_curriculum.py]: *[load_data_curriculum.py]: *[load_data_curriculum.py]: *[load_data_curriculum.py]: *[load_data_curriculum.py]: *[load_data_curriculum.py]: *[load_data_curriculum.py]: *[load_data_curriculum.py]: *[load_data_curriculum.py]: *[load_data_curriculum.py]: *[load_data_curriculum.py]: *[load_data_curriculum.py]: *[load_data_curriculum.py]: *[load_data_curriculum.py]: *[load_data_curriculum.py]: *[load_data_curriculum.py]: *[load_data_curriculum.py]: *[load_data_curriculum.py]: *[load_data_curriculum.py]: *[load_data_curriculum.py]: *[load_data_curriculum.py]: *[load_data_curriculum.py]: *[load_data_curriculum.py]: *[load_data_curriculum.py]: *[load_data_curriculum.py]: *[load_data_curriculum.py]: *[load_data_curriculum.py]: *[load_data_curriculum.py]: *[load_data_curriculum.py]: *[load_data_curriculum.py]: *[load_data_curriculum.py]: *[load_data_curriculum.py]: *[load_data_curriculum.py]: *[load_data_curriculum.py]: *[load_data_curriculum.py]: *[load_data_curriculum.py]: *[load_data_curriculum.py]: *[load_data_curriculum.py]: *[load_data_curriculum.py]: *[load_data_curriculum.py]: *[load_data_curriculum.py]: *[load_data_curriculum.py]: *[load_data_curriculum.py]: *[load_data_curriculum.py]: *[load_data_curriculum.py]: *[load_data_curriculum.py]: *
[load_data_curriculum.py]: Evaluation data size: 953
[load_data_curriculum.py]: Curriculum stage 0 training data size: 4890
[load_data_curriculum.py]: Curriculum stage 1 training data size: 6689
[load_data_curriculum.py]: Curriculum stage 2 training data size: 6690
[load_data.py]: Training data of type 'bad_lang_examples':    5343
[load_data.py]: Training data of type 'short_examples':       699
[load_data.py]: Training data of type 'choose_examples':      13379Namespace(rank=64, learning_rate=4e-07, total_epochs=3, beta=0.1, curriculum_stage=1)
Namespace(rank=64, learning_rate=4e-07, total_epochs=3, beta=0.1, curriculum_stage=1)
Namespace(rank=64, learning_rate=4e-07, total_epochs=3, beta=0.1, curriculum_stage=1)

[load_data.py]: Training data of type 'bad_format_examples': 4e-07
4e-07
4e-07
 4806
[2025-06-12 18:10:01,785] [INFO] [comm.py:658:init_distributed] cdb=None
[2025-06-12 18:10:01,811] [INFO] [comm.py:658:init_distributed] cdb=None
[2025-06-12 18:10:01,828] [INFO] [comm.py:658:init_distributed] cdb=None
[rank3]: Traceback (most recent call last):
[rank3]:   File "/ceph/hpc/home/dv70648/.local/lib/python3.10/site-packages/transformers/utils/hub.py", line 424, in cached_files
[rank3]:     hf_hub_download(
[rank3]:   File "/ceph/hpc/home/dv70648/.local/lib/python3.10/site-packages/huggingface_hub/utils/_validators.py", line 106, in _inner_fn
[rank3]:     validate_repo_id(arg_value)
[rank3]:   File "/ceph/hpc/home/dv70648/.local/lib/python3.10/site-packages/huggingface_hub/utils/_validators.py", line 154, in validate_repo_id
[rank3]:     raise HFValidationError(
[rank3]: huggingface_hub.errors.HFValidationError: Repo id must be in the form 'repo_name' or 'namespace/repo_name': '/ceph/hpc/data/s24o01-42-users/translation_optimization/trl/trained_models/Curriculum_DPO_models/GaMS-9B-DPO-Curriculum-0'. Use `repo_type` argument if needed.

[rank3]: During handling of the above exception, another exception occurred:

[rank3]: Traceback (most recent call last):
[rank3]:   File "/ceph/hpc/data/s24o01-42-users/translation_optimization/trl/train_curriculum.py", line 234, in <module>
[rank3]:     main(get_train_data(CURRICULUM_STAGE), val_data, args.rank, args.learning_rate, args.total_epochs, args.beta, CURRICULUM_STAGE)
[rank3]:   File "/ceph/hpc/data/s24o01-42-users/translation_optimization/trl/train_curriculum.py", line 152, in main
[rank3]:     model = AutoModelForCausalLM.from_pretrained(model_path, attn_implementation="eager")
[rank3]:   File "/ceph/hpc/home/dv70648/.local/lib/python3.10/site-packages/transformers/models/auto/auto_factory.py", line 492, in from_pretrained
[rank3]:     resolved_config_file = cached_file(
[rank3]:   File "/ceph/hpc/home/dv70648/.local/lib/python3.10/site-packages/transformers/utils/hub.py", line 266, in cached_file
[rank3]:     file = cached_files(path_or_repo_id=path_or_repo_id, filenames=[filename], **kwargs)
[rank3]:   File "/ceph/hpc/home/dv70648/.local/lib/python3.10/site-packages/transformers/utils/hub.py", line 470, in cached_files
[rank3]:     resolved_files = [
[rank3]:   File "/ceph/hpc/home/dv70648/.local/lib/python3.10/site-packages/transformers/utils/hub.py", line 471, in <listcomp>
[rank3]:     _get_cache_file_to_return(path_or_repo_id, filename, cache_dir, revision) for filename in full_filenames
[rank3]:   File "/ceph/hpc/home/dv70648/.local/lib/python3.10/site-packages/transformers/utils/hub.py", line 134, in _get_cache_file_to_return
[rank3]:     resolved_file = try_to_load_from_cache(path_or_repo_id, full_filename, cache_dir=cache_dir, revision=revision)
[rank3]:   File "/ceph/hpc/home/dv70648/.local/lib/python3.10/site-packages/huggingface_hub/utils/_validators.py", line 106, in _inner_fn
[rank3]:     validate_repo_id(arg_value)
[rank3]:   File "/ceph/hpc/home/dv70648/.local/lib/python3.10/site-packages/huggingface_hub/utils/_validators.py", line 154, in validate_repo_id
[rank3]:     raise HFValidationError(
[rank3]: huggingface_hub.errors.HFValidationError: Repo id must be in the form 'repo_name' or 'namespace/repo_name': '/ceph/hpc/data/s24o01-42-users/translation_optimization/trl/trained_models/Curriculum_DPO_models/GaMS-9B-DPO-Curriculum-0'. Use `repo_type` argument if needed.
[rank1]: Traceback (most recent call last):
[rank1]:   File "/ceph/hpc/home/dv70648/.local/lib/python3.10/site-packages/transformers/utils/hub.py", line 424, in cached_files
[rank1]:     hf_hub_download(
[rank1]:   File "/ceph/hpc/home/dv70648/.local/lib/python3.10/site-packages/huggingface_hub/utils/_validators.py", line 106, in _inner_fn
[rank1]:     validate_repo_id(arg_value)
[rank1]:   File "/ceph/hpc/home/dv70648/.local/lib/python3.10/site-packages/huggingface_hub/utils/_validators.py", line 154, in validate_repo_id
[rank1]:     raise HFValidationError(
[rank1]: huggingface_hub.errors.HFValidationError: Repo id must be in the form 'repo_name' or 'namespace/repo_name': '/ceph/hpc/data/s24o01-42-users/translation_optimization/trl/trained_models/Curriculum_DPO_models/GaMS-9B-DPO-Curriculum-0'. Use `repo_type` argument if needed.

[rank1]: During handling of the above exception, another exception occurred:

[rank1]: Traceback (most recent call last):
[rank1]:   File "/ceph/hpc/data/s24o01-42-users/translation_optimization/trl/train_curriculum.py", line 234, in <module>
[rank1]:     main(get_train_data(CURRICULUM_STAGE), val_data, args.rank, args.learning_rate, args.total_epochs, args.beta, CURRICULUM_STAGE)
[rank1]:   File "/ceph/hpc/data/s24o01-42-users/translation_optimization/trl/train_curriculum.py", line 152, in main
[rank1]:     model = AutoModelForCausalLM.from_pretrained(model_path, attn_implementation="eager")
[rank1]:   File "/ceph/hpc/home/dv70648/.local/lib/python3.10/site-packages/transformers/models/auto/auto_factory.py", line 492, in from_pretrained
[rank1]:     resolved_config_file = cached_file(
[rank1]:   File "/ceph/hpc/home/dv70648/.local/lib/python3.10/site-packages/transformers/utils/hub.py", line 266, in cached_file
[rank1]:     file = cached_files(path_or_repo_id=path_or_repo_id, filenames=[filename], **kwargs)
[rank1]:   File "/ceph/hpc/home/dv70648/.local/lib/python3.10/site-packages/transformers/utils/hub.py", line 470, in cached_files
[rank1]:     resolved_files = [
[rank1]:   File "/ceph/hpc/home/dv70648/.local/lib/python3.10/site-packages/transformers/utils/hub.py", line 471, in <listcomp>
[rank1]:     _get_cache_file_to_return(path_or_repo_id, filename, cache_dir, revision) for filename in full_filenames
[rank1]:   File "/ceph/hpc/home/dv70648/.local/lib/python3.10/site-packages/transformers/utils/hub.py", line 134, in _get_cache_file_to_return
[rank1]:     resolved_file = try_to_load_from_cache(path_or_repo_id, full_filename, cache_dir=cache_dir, revision=revision)
[rank1]:   File "/ceph/hpc/home/dv70648/.local/lib/python3.10/site-packages/huggingface_hub/utils/_validators.py", line 106, in _inner_fn
[rank1]:     validate_repo_id(arg_value)
[rank1]:   File "/ceph/hpc/home/dv70648/.local/lib/python3.10/site-packages/huggingface_hub/utils/_validators.py", line 154, in validate_repo_id
[rank1]:     raise HFValidationError(
[rank1]: huggingface_hub.errors.HFValidationError: Repo id must be in the form 'repo_name' or 'namespace/repo_name': '/ceph/hpc/data/s24o01-42-users/translation_optimization/trl/trained_models/Curriculum_DPO_models/GaMS-9B-DPO-Curriculum-0'. Use `repo_type` argument if needed.
[rank2]: Traceback (most recent call last):
[rank2]:   File "/ceph/hpc/home/dv70648/.local/lib/python3.10/site-packages/transformers/utils/hub.py", line 424, in cached_files
[rank2]:     hf_hub_download(
[rank2]:   File "/ceph/hpc/home/dv70648/.local/lib/python3.10/site-packages/huggingface_hub/utils/_validators.py", line 106, in _inner_fn
[rank2]:     validate_repo_id(arg_value)
[rank2]:   File "/ceph/hpc/home/dv70648/.local/lib/python3.10/site-packages/huggingface_hub/utils/_validators.py", line 154, in validate_repo_id
[rank2]:     raise HFValidationError(
[rank2]: huggingface_hub.errors.HFValidationError: Repo id must be in the form 'repo_name' or 'namespace/repo_name': '/ceph/hpc/data/s24o01-42-users/translation_optimization/trl/trained_models/Curriculum_DPO_models/GaMS-9B-DPO-Curriculum-0'. Use `repo_type` argument if needed.

[rank2]: During handling of the above exception, another exception occurred:

[rank2]: Traceback (most recent call last):
[rank2]:   File "/ceph/hpc/data/s24o01-42-users/translation_optimization/trl/train_curriculum.py", line 234, in <module>
[rank2]:     main(get_train_data(CURRICULUM_STAGE), val_data, args.rank, args.learning_rate, args.total_epochs, args.beta, CURRICULUM_STAGE)
[rank2]:   File "/ceph/hpc/data/s24o01-42-users/translation_optimization/trl/train_curriculum.py", line 152, in main
[rank2]:     model = AutoModelForCausalLM.from_pretrained(model_path, attn_implementation="eager")
[rank2]:   File "/ceph/hpc/home/dv70648/.local/lib/python3.10/site-packages/transformers/models/auto/auto_factory.py", line 492, in from_pretrained
[rank2]:     resolved_config_file = cached_file(
[rank2]:   File "/ceph/hpc/home/dv70648/.local/lib/python3.10/site-packages/transformers/utils/hub.py", line 266, in cached_file
[rank2]:     file = cached_files(path_or_repo_id=path_or_repo_id, filenames=[filename], **kwargs)
[rank2]:   File "/ceph/hpc/home/dv70648/.local/lib/python3.10/site-packages/transformers/utils/hub.py", line 470, in cached_files
[rank2]:     resolved_files = [
[rank2]:   File "/ceph/hpc/home/dv70648/.local/lib/python3.10/site-packages/transformers/utils/hub.py", line 471, in <listcomp>
[rank2]:     _get_cache_file_to_return(path_or_repo_id, filename, cache_dir, revision) for filename in full_filenames
[rank2]:   File "/ceph/hpc/home/dv70648/.local/lib/python3.10/site-packages/transformers/utils/hub.py", line 134, in _get_cache_file_to_return
[rank2]:     resolved_file = try_to_load_from_cache(path_or_repo_id, full_filename, cache_dir=cache_dir, revision=revision)
[rank2]:   File "/ceph/hpc/home/dv70648/.local/lib/python3.10/site-packages/huggingface_hub/utils/_validators.py", line 106, in _inner_fn
[rank2]:     validate_repo_id(arg_value)
[rank2]:   File "/ceph/hpc/home/dv70648/.local/lib/python3.10/site-packages/huggingface_hub/utils/_validators.py", line 154, in validate_repo_id
[rank2]:     raise HFValidationError(
[rank2]: huggingface_hub.errors.HFValidationError: Repo id must be in the form 'repo_name' or 'namespace/repo_name': '/ceph/hpc/data/s24o01-42-users/translation_optimization/trl/trained_models/Curriculum_DPO_models/GaMS-9B-DPO-Curriculum-0'. Use `repo_type` argument if needed.
[load_data.py]: Number of training examples: 24227
[load_data.py]: Number of validation examples: 953
Namespace(rank=64, learning_rate=4e-07, total_epochs=3, beta=0.1, curriculum_stage=1)
4e-07
World size: 12
Setting gradient accumulation steps to: 1
Created datasets
Train dataset size: 6689
Validation dataset size: 953
Steps per epoch: 418
Evaluate each 209 steps
[2025-06-12 18:10:03,798] [INFO] [comm.py:658:init_distributed] cdb=None
[2025-06-12 18:10:03,803] [INFO] [comm.py:689:init_distributed] Initializing TorchBackend in DeepSpeed with backend nccl
Set up DPO configuration
Loading model from: /ceph/hpc/data/s24o01-42-users/translation_optimization/trl/trained_models/Curriculum_DPO_models/GaMS-9B-DPO-Curriculum-0
[rank0]: Traceback (most recent call last):
[rank0]:   File "/ceph/hpc/home/dv70648/.local/lib/python3.10/site-packages/transformers/utils/hub.py", line 424, in cached_files
[rank0]:     hf_hub_download(
[rank0]:   File "/ceph/hpc/home/dv70648/.local/lib/python3.10/site-packages/huggingface_hub/utils/_validators.py", line 106, in _inner_fn
[rank0]:     validate_repo_id(arg_value)
[rank0]:   File "/ceph/hpc/home/dv70648/.local/lib/python3.10/site-packages/huggingface_hub/utils/_validators.py", line 154, in validate_repo_id
[rank0]:     raise HFValidationError(
[rank0]: huggingface_hub.errors.HFValidationError: Repo id must be in the form 'repo_name' or 'namespace/repo_name': '/ceph/hpc/data/s24o01-42-users/translation_optimization/trl/trained_models/Curriculum_DPO_models/GaMS-9B-DPO-Curriculum-0'. Use `repo_type` argument if needed.

[rank0]: During handling of the above exception, another exception occurred:

[rank0]: Traceback (most recent call last):
[rank0]:   File "/ceph/hpc/data/s24o01-42-users/translation_optimization/trl/train_curriculum.py", line 234, in <module>
[rank0]:     main(get_train_data(CURRICULUM_STAGE), val_data, args.rank, args.learning_rate, args.total_epochs, args.beta, CURRICULUM_STAGE)
[rank0]:   File "/ceph/hpc/data/s24o01-42-users/translation_optimization/trl/train_curriculum.py", line 152, in main
[rank0]:     model = AutoModelForCausalLM.from_pretrained(model_path, attn_implementation="eager")
[rank0]:   File "/ceph/hpc/home/dv70648/.local/lib/python3.10/site-packages/transformers/models/auto/auto_factory.py", line 492, in from_pretrained
[rank0]:     resolved_config_file = cached_file(
[rank0]:   File "/ceph/hpc/home/dv70648/.local/lib/python3.10/site-packages/transformers/utils/hub.py", line 266, in cached_file
[rank0]:     file = cached_files(path_or_repo_id=path_or_repo_id, filenames=[filename], **kwargs)
[rank0]:   File "/ceph/hpc/home/dv70648/.local/lib/python3.10/site-packages/transformers/utils/hub.py", line 470, in cached_files
[rank0]:     resolved_files = [
[rank0]:   File "/ceph/hpc/home/dv70648/.local/lib/python3.10/site-packages/transformers/utils/hub.py", line 471, in <listcomp>
[rank0]:     _get_cache_file_to_return(path_or_repo_id, filename, cache_dir, revision) for filename in full_filenames
[rank0]:   File "/ceph/hpc/home/dv70648/.local/lib/python3.10/site-packages/transformers/utils/hub.py", line 134, in _get_cache_file_to_return
[rank0]:     resolved_file = try_to_load_from_cache(path_or_repo_id, full_filename, cache_dir=cache_dir, revision=revision)
[rank0]:   File "/ceph/hpc/home/dv70648/.local/lib/python3.10/site-packages/huggingface_hub/utils/_validators.py", line 106, in _inner_fn
[rank0]:     validate_repo_id(arg_value)
[rank0]:   File "/ceph/hpc/home/dv70648/.local/lib/python3.10/site-packages/huggingface_hub/utils/_validators.py", line 154, in validate_repo_id
[rank0]:     raise HFValidationError(
[rank0]: huggingface_hub.errors.HFValidationError: Repo id must be in the form 'repo_name' or 'namespace/repo_name': '/ceph/hpc/data/s24o01-42-users/translation_optimization/trl/trained_models/Curriculum_DPO_models/GaMS-9B-DPO-Curriculum-0'. Use `repo_type` argument if needed.
W0612 18:10:04.572000 3233343 torch/distributed/elastic/multiprocessing/api.py:897] Sending process 3233535 closing signal SIGTERM
W0612 18:10:04.595000 3233343 torch/distributed/elastic/multiprocessing/api.py:897] Sending process 3233537 closing signal SIGTERM
E0612 18:10:04.884000 3233343 torch/distributed/elastic/multiprocessing/api.py:869] failed (exitcode: 1) local_rank: 1 (pid: 3233536) of binary: /usr/bin/python3
Traceback (most recent call last):
  File "/usr/local/bin/accelerate", line 8, in <module>
    sys.exit(main())
  File "/usr/local/lib/python3.10/dist-packages/accelerate/commands/accelerate_cli.py", line 48, in main
    args.func(args)
  File "/usr/local/lib/python3.10/dist-packages/accelerate/commands/launch.py", line 1182, in launch_command
    deepspeed_launcher(args)
  File "/usr/local/lib/python3.10/dist-packages/accelerate/commands/launch.py", line 861, in deepspeed_launcher
    distrib_run.run(args)
  File "/usr/local/lib/python3.10/dist-packages/torch/distributed/run.py", line 909, in run
    elastic_launch(
  File "/usr/local/lib/python3.10/dist-packages/torch/distributed/launcher/api.py", line 138, in __call__
    return launch_agent(self._config, self._entrypoint, list(args))
  File "/usr/local/lib/python3.10/dist-packages/torch/distributed/launcher/api.py", line 269, in launch_agent
    raise ChildFailedError(
torch.distributed.elastic.multiprocessing.errors.ChildFailedError: 
============================================================
train_curriculum.py FAILED
------------------------------------------------------------
Failures:
  <NO_OTHER_FAILURES>
------------------------------------------------------------
Root Cause (first observed failure):
[0]:
  time      : 2025-06-12_18:10:04
  host      : pm5-nod00.vega.pri
  rank      : 1 (local_rank: 1)
  exitcode  : 1 (pid: 3233536)
  error_file: <N/A>
  traceback : To enable traceback see: https://pytorch.org/docs/stable/elastic/errors.html
============================================================
